<<<<<<< HEAD
2022-02-22 10:56:44,567 :INFO : test_user_authenticate :URL is provided
2022-02-22 10:56:44,584 :INFO : test_login_user :URL is provided
2022-02-22 10:56:44,604 :INFO : test_login_user :Exception occurred please find details below
2022-02-22 10:56:44,604 :INFO : test_login_user :Exception occurred please find details below
2022-02-22 10:56:44,604 :ERROR : test_login_user :'Worksheet Headers does not exist.'
Traceback (most recent call last):
  File "/Users/firdi/OneDrive - Deloitte (O365D)/Training/Main_API_Project/User/User_Login.py", line 22, in test_login_user
    header_dict = e1.getAPIData("Headers", "Header")
  File "/Users/firdi/OneDrive - Deloitte (O365D)/Training/Main_API_Project/Data_Config/Excel.py", line 19, in getAPIData
    sheet = book.get_sheet_by_name(data_section)
  File "/Users/firdi/OneDrive - Deloitte (O365D)/Training/Main_API_Project/venv/lib/python3.9/site-packages/openpyxl/compat/__init__.py", line 38, in new_func1
    return func1(*args, **kwargs)
  File "/Users/firdi/OneDrive - Deloitte (O365D)/Training/Main_API_Project/venv/lib/python3.9/site-packages/openpyxl/workbook/workbook.py", line 262, in get_sheet_by_name
    return self[name]
  File "/Users/firdi/OneDrive - Deloitte (O365D)/Training/Main_API_Project/venv/lib/python3.9/site-packages/openpyxl/workbook/workbook.py", line 288, in __getitem__
    raise KeyError("Worksheet {0} does not exist.".format(key))
KeyError: 'Worksheet Headers does not exist.'
2022-02-22 10:56:44,604 :ERROR : test_login_user :'Worksheet Headers does not exist.'
Traceback (most recent call last):
  File "/Users/firdi/OneDrive - Deloitte (O365D)/Training/Main_API_Project/User/User_Login.py", line 22, in test_login_user
    header_dict = e1.getAPIData("Headers", "Header")
  File "/Users/firdi/OneDrive - Deloitte (O365D)/Training/Main_API_Project/Data_Config/Excel.py", line 19, in getAPIData
    sheet = book.get_sheet_by_name(data_section)
  File "/Users/firdi/OneDrive - Deloitte (O365D)/Training/Main_API_Project/venv/lib/python3.9/site-packages/openpyxl/compat/__init__.py", line 38, in new_func1
    return func1(*args, **kwargs)
  File "/Users/firdi/OneDrive - Deloitte (O365D)/Training/Main_API_Project/venv/lib/python3.9/site-packages/openpyxl/workbook/workbook.py", line 262, in get_sheet_by_name
    return self[name]
  File "/Users/firdi/OneDrive - Deloitte (O365D)/Training/Main_API_Project/venv/lib/python3.9/site-packages/openpyxl/workbook/workbook.py", line 288, in __getitem__
    raise KeyError("Worksheet {0} does not exist.".format(key))
KeyError: 'Worksheet Headers does not exist.'
2022-02-22 10:56:44,607 :INFO : test_user_authenticate :Exception occurred please find details below
2022-02-22 10:56:44,607 :INFO : test_user_authenticate :Exception occurred please find details below
2022-02-22 10:56:44,607 :ERROR : test_user_authenticate :
Traceback (most recent call last):
  File "/Users/firdi/OneDrive - Deloitte (O365D)/Training/Main_API_Project/User/User_Login.py", line 22, in test_login_user
    header_dict = e1.getAPIData("Headers", "Header")
  File "/Users/firdi/OneDrive - Deloitte (O365D)/Training/Main_API_Project/Data_Config/Excel.py", line 19, in getAPIData
    sheet = book.get_sheet_by_name(data_section)
  File "/Users/firdi/OneDrive - Deloitte (O365D)/Training/Main_API_Project/venv/lib/python3.9/site-packages/openpyxl/compat/__init__.py", line 38, in new_func1
    return func1(*args, **kwargs)
  File "/Users/firdi/OneDrive - Deloitte (O365D)/Training/Main_API_Project/venv/lib/python3.9/site-packages/openpyxl/workbook/workbook.py", line 262, in get_sheet_by_name
    return self[name]
  File "/Users/firdi/OneDrive - Deloitte (O365D)/Training/Main_API_Project/venv/lib/python3.9/site-packages/openpyxl/workbook/workbook.py", line 288, in __getitem__
=======
2022-02-21 15:51:08,558 :INFO : test_user_currentUser :URL is provided
2022-02-21 15:51:08,579 :INFO : test_login_user :URL is provided
2022-02-21 15:51:08,596 :INFO : test_login_user :Exception occurred please find details below
2022-02-21 15:51:08,596 :INFO : test_login_user :Exception occurred please find details below
2022-02-21 15:51:08,596 :ERROR : test_login_user :'Worksheet Headers does not exist.'
Traceback (most recent call last):
  File "/Users/mohdsalekhan/Documents/HQM_API/Main_Project_API/User/User_Login.py", line 22, in test_login_user
    header_dict = e1.getAPIData("Headers", "Header")
  File "/Users/mohdsalekhan/Documents/HQM_API/Main_Project_API/Data_Config/Excel.py", line 19, in getAPIData
    sheet = book.get_sheet_by_name(data_section)
  File "/Users/mohdsalekhan/Library/Python/3.9/lib/python/site-packages/openpyxl/compat/__init__.py", line 38, in new_func1
    return func1(*args, **kwargs)
  File "/Users/mohdsalekhan/Library/Python/3.9/lib/python/site-packages/openpyxl/workbook/workbook.py", line 262, in get_sheet_by_name
    return self[name]
  File "/Users/mohdsalekhan/Library/Python/3.9/lib/python/site-packages/openpyxl/workbook/workbook.py", line 288, in __getitem__
    raise KeyError("Worksheet {0} does not exist.".format(key))
KeyError: 'Worksheet Headers does not exist.'
2022-02-21 15:51:08,596 :ERROR : test_login_user :'Worksheet Headers does not exist.'
Traceback (most recent call last):
  File "/Users/mohdsalekhan/Documents/HQM_API/Main_Project_API/User/User_Login.py", line 22, in test_login_user
    header_dict = e1.getAPIData("Headers", "Header")
  File "/Users/mohdsalekhan/Documents/HQM_API/Main_Project_API/Data_Config/Excel.py", line 19, in getAPIData
    sheet = book.get_sheet_by_name(data_section)
  File "/Users/mohdsalekhan/Library/Python/3.9/lib/python/site-packages/openpyxl/compat/__init__.py", line 38, in new_func1
    return func1(*args, **kwargs)
  File "/Users/mohdsalekhan/Library/Python/3.9/lib/python/site-packages/openpyxl/workbook/workbook.py", line 262, in get_sheet_by_name
    return self[name]
  File "/Users/mohdsalekhan/Library/Python/3.9/lib/python/site-packages/openpyxl/workbook/workbook.py", line 288, in __getitem__
    raise KeyError("Worksheet {0} does not exist.".format(key))
KeyError: 'Worksheet Headers does not exist.'
2022-02-21 15:51:08,602 :INFO : test_user_currentUser :Exception occurred please find details below
2022-02-21 15:51:08,602 :INFO : test_user_currentUser :Exception occurred please find details below
2022-02-21 15:51:08,603 :ERROR : test_user_currentUser :
Traceback (most recent call last):
  File "/Users/mohdsalekhan/Documents/HQM_API/Main_Project_API/User/User_Login.py", line 22, in test_login_user
    header_dict = e1.getAPIData("Headers", "Header")
  File "/Users/mohdsalekhan/Documents/HQM_API/Main_Project_API/Data_Config/Excel.py", line 19, in getAPIData
    sheet = book.get_sheet_by_name(data_section)
  File "/Users/mohdsalekhan/Library/Python/3.9/lib/python/site-packages/openpyxl/compat/__init__.py", line 38, in new_func1
    return func1(*args, **kwargs)
  File "/Users/mohdsalekhan/Library/Python/3.9/lib/python/site-packages/openpyxl/workbook/workbook.py", line 262, in get_sheet_by_name
    return self[name]
  File "/Users/mohdsalekhan/Library/Python/3.9/lib/python/site-packages/openpyxl/workbook/workbook.py", line 288, in __getitem__
>>>>>>> e2e38304767dce09a8d4e85ce77f80fd016bd0ae
    raise KeyError("Worksheet {0} does not exist.".format(key))
KeyError: 'Worksheet Headers does not exist.'

During handling of the above exception, another exception occurred:

Traceback (most recent call last):
<<<<<<< HEAD
  File "/Users/firdi/OneDrive - Deloitte (O365D)/Training/Main_API_Project/User/User_Authenticate.py", line 28, in test_user_authenticate
    header = {'Authorization': 'Bearer '+login.test_login_user()}
  File "/Users/firdi/OneDrive - Deloitte (O365D)/Training/Main_API_Project/User/User_Login.py", line 53, in test_login_user
    assert False
AssertionError
2022-02-22 10:56:44,607 :ERROR : test_user_authenticate :
Traceback (most recent call last):
  File "/Users/firdi/OneDrive - Deloitte (O365D)/Training/Main_API_Project/User/User_Login.py", line 22, in test_login_user
    header_dict = e1.getAPIData("Headers", "Header")
  File "/Users/firdi/OneDrive - Deloitte (O365D)/Training/Main_API_Project/Data_Config/Excel.py", line 19, in getAPIData
    sheet = book.get_sheet_by_name(data_section)
  File "/Users/firdi/OneDrive - Deloitte (O365D)/Training/Main_API_Project/venv/lib/python3.9/site-packages/openpyxl/compat/__init__.py", line 38, in new_func1
    return func1(*args, **kwargs)
  File "/Users/firdi/OneDrive - Deloitte (O365D)/Training/Main_API_Project/venv/lib/python3.9/site-packages/openpyxl/workbook/workbook.py", line 262, in get_sheet_by_name
    return self[name]
  File "/Users/firdi/OneDrive - Deloitte (O365D)/Training/Main_API_Project/venv/lib/python3.9/site-packages/openpyxl/workbook/workbook.py", line 288, in __getitem__
=======
  File "/Users/mohdsalekhan/Documents/HQM_API/Main_Project_API/User/User_CurrentUser.py", line 29, in test_user_currentUser
    "Authorization": 'Bearer ' + login.test_login_user()}
  File "/Users/mohdsalekhan/Documents/HQM_API/Main_Project_API/User/User_Login.py", line 53, in test_login_user
    assert False
AssertionError
2022-02-21 15:51:08,603 :ERROR : test_user_currentUser :
Traceback (most recent call last):
  File "/Users/mohdsalekhan/Documents/HQM_API/Main_Project_API/User/User_Login.py", line 22, in test_login_user
    header_dict = e1.getAPIData("Headers", "Header")
  File "/Users/mohdsalekhan/Documents/HQM_API/Main_Project_API/Data_Config/Excel.py", line 19, in getAPIData
    sheet = book.get_sheet_by_name(data_section)
  File "/Users/mohdsalekhan/Library/Python/3.9/lib/python/site-packages/openpyxl/compat/__init__.py", line 38, in new_func1
    return func1(*args, **kwargs)
  File "/Users/mohdsalekhan/Library/Python/3.9/lib/python/site-packages/openpyxl/workbook/workbook.py", line 262, in get_sheet_by_name
    return self[name]
  File "/Users/mohdsalekhan/Library/Python/3.9/lib/python/site-packages/openpyxl/workbook/workbook.py", line 288, in __getitem__
>>>>>>> e2e38304767dce09a8d4e85ce77f80fd016bd0ae
    raise KeyError("Worksheet {0} does not exist.".format(key))
KeyError: 'Worksheet Headers does not exist.'

During handling of the above exception, another exception occurred:

Traceback (most recent call last):
<<<<<<< HEAD
  File "/Users/firdi/OneDrive - Deloitte (O365D)/Training/Main_API_Project/User/User_Authenticate.py", line 28, in test_user_authenticate
    header = {'Authorization': 'Bearer '+login.test_login_user()}
  File "/Users/firdi/OneDrive - Deloitte (O365D)/Training/Main_API_Project/User/User_Login.py", line 53, in test_login_user
    assert False
AssertionError
2022-02-22 11:00:56,201 :INFO : test_user_authenticate :URL is provided
2022-02-22 11:00:56,204 :INFO : test_login_user :Logging in as admin
2022-02-22 11:00:56,220 :INFO : test_login_user :Fetching payload data for admin
2022-02-22 11:00:57,033 :INFO : test_login_user :Bearer token is 
2022-02-22 11:00:57,033 :INFO : test_login_user :eyJhbGciOiJIUzI1NiJ9.eyJzdWIiOiJtYWRhcmEiLCJleHAiOjE2NDU1Nzk4NTcsImlhdCI6MTY0NTUwNzg1N30.4TvrKjz2c_sR2w2YQwyTEAQ_dikWc-S10Axib1035Lw
2022-02-22 11:00:57,033 :INFO : test_login_user :200
2022-02-22 11:00:57,033 :INFO : test_login_user :Successfully Logged in
2022-02-22 11:00:57,033 :INFO : test_user_authenticate :Header is provided
2022-02-22 11:00:57,377 :INFO : test_user_authenticate :Response is as below
2022-02-22 11:00:57,377 :INFO : test_user_authenticate :<Response [200]>
2022-02-22 11:00:57,377 :INFO : test_user_authenticate :Status code is validated
=======
  File "/Users/mohdsalekhan/Documents/HQM_API/Main_Project_API/User/User_CurrentUser.py", line 29, in test_user_currentUser
    "Authorization": 'Bearer ' + login.test_login_user()}
  File "/Users/mohdsalekhan/Documents/HQM_API/Main_Project_API/User/User_Login.py", line 53, in test_login_user
    assert False
AssertionError
2022-02-21 15:52:30,138 :INFO : test_get_user_by_user_ID :URL is provided
2022-02-21 15:52:30,157 :INFO : test_login_user :URL is provided
2022-02-21 15:52:30,176 :INFO : test_login_user :Exception occurred please find details below
2022-02-21 15:52:30,176 :INFO : test_login_user :Exception occurred please find details below
2022-02-21 15:52:30,177 :ERROR : test_login_user :'Worksheet Headers does not exist.'
Traceback (most recent call last):
  File "/Users/mohdsalekhan/Documents/HQM_API/Main_Project_API/User/User_Login.py", line 22, in test_login_user
    header_dict = e1.getAPIData("Headers", "Header")
  File "/Users/mohdsalekhan/Documents/HQM_API/Main_Project_API/Data_Config/Excel.py", line 19, in getAPIData
    sheet = book.get_sheet_by_name(data_section)
  File "/Users/mohdsalekhan/Library/Python/3.9/lib/python/site-packages/openpyxl/compat/__init__.py", line 38, in new_func1
    return func1(*args, **kwargs)
  File "/Users/mohdsalekhan/Library/Python/3.9/lib/python/site-packages/openpyxl/workbook/workbook.py", line 262, in get_sheet_by_name
    return self[name]
  File "/Users/mohdsalekhan/Library/Python/3.9/lib/python/site-packages/openpyxl/workbook/workbook.py", line 288, in __getitem__
    raise KeyError("Worksheet {0} does not exist.".format(key))
KeyError: 'Worksheet Headers does not exist.'
2022-02-21 15:52:30,177 :ERROR : test_login_user :'Worksheet Headers does not exist.'
Traceback (most recent call last):
  File "/Users/mohdsalekhan/Documents/HQM_API/Main_Project_API/User/User_Login.py", line 22, in test_login_user
    header_dict = e1.getAPIData("Headers", "Header")
  File "/Users/mohdsalekhan/Documents/HQM_API/Main_Project_API/Data_Config/Excel.py", line 19, in getAPIData
    sheet = book.get_sheet_by_name(data_section)
  File "/Users/mohdsalekhan/Library/Python/3.9/lib/python/site-packages/openpyxl/compat/__init__.py", line 38, in new_func1
    return func1(*args, **kwargs)
  File "/Users/mohdsalekhan/Library/Python/3.9/lib/python/site-packages/openpyxl/workbook/workbook.py", line 262, in get_sheet_by_name
    return self[name]
  File "/Users/mohdsalekhan/Library/Python/3.9/lib/python/site-packages/openpyxl/workbook/workbook.py", line 288, in __getitem__
    raise KeyError("Worksheet {0} does not exist.".format(key))
KeyError: 'Worksheet Headers does not exist.'
2022-02-21 15:52:30,180 :INFO : test_get_user_by_user_ID :Exception occurred please find details below
2022-02-21 15:52:30,180 :INFO : test_get_user_by_user_ID :Exception occurred please find details below
2022-02-21 15:52:30,180 :ERROR : test_get_user_by_user_ID :
Traceback (most recent call last):
  File "/Users/mohdsalekhan/Documents/HQM_API/Main_Project_API/User/User_Login.py", line 22, in test_login_user
    header_dict = e1.getAPIData("Headers", "Header")
  File "/Users/mohdsalekhan/Documents/HQM_API/Main_Project_API/Data_Config/Excel.py", line 19, in getAPIData
    sheet = book.get_sheet_by_name(data_section)
  File "/Users/mohdsalekhan/Library/Python/3.9/lib/python/site-packages/openpyxl/compat/__init__.py", line 38, in new_func1
    return func1(*args, **kwargs)
  File "/Users/mohdsalekhan/Library/Python/3.9/lib/python/site-packages/openpyxl/workbook/workbook.py", line 262, in get_sheet_by_name
    return self[name]
  File "/Users/mohdsalekhan/Library/Python/3.9/lib/python/site-packages/openpyxl/workbook/workbook.py", line 288, in __getitem__
    raise KeyError("Worksheet {0} does not exist.".format(key))
KeyError: 'Worksheet Headers does not exist.'

During handling of the above exception, another exception occurred:

Traceback (most recent call last):
  File "/Users/mohdsalekhan/Documents/HQM_API/Main_Project_API/User/User_GetUserByUserID.py", line 23, in test_get_user_by_user_ID
    "Authorization": 'Bearer '+login.test_login_user()}
  File "/Users/mohdsalekhan/Documents/HQM_API/Main_Project_API/User/User_Login.py", line 53, in test_login_user
    assert False
AssertionError
2022-02-21 15:52:30,180 :ERROR : test_get_user_by_user_ID :
Traceback (most recent call last):
  File "/Users/mohdsalekhan/Documents/HQM_API/Main_Project_API/User/User_Login.py", line 22, in test_login_user
    header_dict = e1.getAPIData("Headers", "Header")
  File "/Users/mohdsalekhan/Documents/HQM_API/Main_Project_API/Data_Config/Excel.py", line 19, in getAPIData
    sheet = book.get_sheet_by_name(data_section)
  File "/Users/mohdsalekhan/Library/Python/3.9/lib/python/site-packages/openpyxl/compat/__init__.py", line 38, in new_func1
    return func1(*args, **kwargs)
  File "/Users/mohdsalekhan/Library/Python/3.9/lib/python/site-packages/openpyxl/workbook/workbook.py", line 262, in get_sheet_by_name
    return self[name]
  File "/Users/mohdsalekhan/Library/Python/3.9/lib/python/site-packages/openpyxl/workbook/workbook.py", line 288, in __getitem__
    raise KeyError("Worksheet {0} does not exist.".format(key))
KeyError: 'Worksheet Headers does not exist.'

During handling of the above exception, another exception occurred:

Traceback (most recent call last):
  File "/Users/mohdsalekhan/Documents/HQM_API/Main_Project_API/User/User_GetUserByUserID.py", line 23, in test_get_user_by_user_ID
    "Authorization": 'Bearer '+login.test_login_user()}
  File "/Users/mohdsalekhan/Documents/HQM_API/Main_Project_API/User/User_Login.py", line 53, in test_login_user
    assert False
AssertionError
2022-02-21 15:54:57,609 :INFO : test_user_currentUser :URL is provided
2022-02-21 15:54:57,627 :INFO : test_login_user :URL is provided
2022-02-21 15:54:57,647 :INFO : test_login_user :Exception occurred please find details below
2022-02-21 15:54:57,647 :INFO : test_login_user :Exception occurred please find details below
2022-02-21 15:54:57,647 :ERROR : test_login_user :'Worksheet Headers does not exist.'
Traceback (most recent call last):
  File "/Users/mohdsalekhan/Documents/HQM_API/Main_Project_API/User/User_Login.py", line 22, in test_login_user
    header_dict = e1.getAPIData("Headers", "Header")
  File "/Users/mohdsalekhan/Documents/HQM_API/Main_Project_API/Data_Config/Excel.py", line 19, in getAPIData
    sheet = book.get_sheet_by_name(data_section)
  File "/Users/mohdsalekhan/Library/Python/3.9/lib/python/site-packages/openpyxl/compat/__init__.py", line 38, in new_func1
    return func1(*args, **kwargs)
  File "/Users/mohdsalekhan/Library/Python/3.9/lib/python/site-packages/openpyxl/workbook/workbook.py", line 262, in get_sheet_by_name
    return self[name]
  File "/Users/mohdsalekhan/Library/Python/3.9/lib/python/site-packages/openpyxl/workbook/workbook.py", line 288, in __getitem__
    raise KeyError("Worksheet {0} does not exist.".format(key))
KeyError: 'Worksheet Headers does not exist.'
2022-02-21 15:54:57,647 :ERROR : test_login_user :'Worksheet Headers does not exist.'
Traceback (most recent call last):
  File "/Users/mohdsalekhan/Documents/HQM_API/Main_Project_API/User/User_Login.py", line 22, in test_login_user
    header_dict = e1.getAPIData("Headers", "Header")
  File "/Users/mohdsalekhan/Documents/HQM_API/Main_Project_API/Data_Config/Excel.py", line 19, in getAPIData
    sheet = book.get_sheet_by_name(data_section)
  File "/Users/mohdsalekhan/Library/Python/3.9/lib/python/site-packages/openpyxl/compat/__init__.py", line 38, in new_func1
    return func1(*args, **kwargs)
  File "/Users/mohdsalekhan/Library/Python/3.9/lib/python/site-packages/openpyxl/workbook/workbook.py", line 262, in get_sheet_by_name
    return self[name]
  File "/Users/mohdsalekhan/Library/Python/3.9/lib/python/site-packages/openpyxl/workbook/workbook.py", line 288, in __getitem__
    raise KeyError("Worksheet {0} does not exist.".format(key))
KeyError: 'Worksheet Headers does not exist.'
2022-02-21 15:54:57,652 :INFO : test_user_currentUser :Exception occurred please find details below
2022-02-21 15:54:57,652 :INFO : test_user_currentUser :Exception occurred please find details below
2022-02-21 15:54:57,652 :ERROR : test_user_currentUser :
Traceback (most recent call last):
  File "/Users/mohdsalekhan/Documents/HQM_API/Main_Project_API/User/User_Login.py", line 22, in test_login_user
    header_dict = e1.getAPIData("Headers", "Header")
  File "/Users/mohdsalekhan/Documents/HQM_API/Main_Project_API/Data_Config/Excel.py", line 19, in getAPIData
    sheet = book.get_sheet_by_name(data_section)
  File "/Users/mohdsalekhan/Library/Python/3.9/lib/python/site-packages/openpyxl/compat/__init__.py", line 38, in new_func1
    return func1(*args, **kwargs)
  File "/Users/mohdsalekhan/Library/Python/3.9/lib/python/site-packages/openpyxl/workbook/workbook.py", line 262, in get_sheet_by_name
    return self[name]
  File "/Users/mohdsalekhan/Library/Python/3.9/lib/python/site-packages/openpyxl/workbook/workbook.py", line 288, in __getitem__
    raise KeyError("Worksheet {0} does not exist.".format(key))
KeyError: 'Worksheet Headers does not exist.'

During handling of the above exception, another exception occurred:

Traceback (most recent call last):
  File "/Users/mohdsalekhan/Documents/HQM_API/Main_Project_API/User/User_CurrentUser.py", line 29, in test_user_currentUser
    "Authorization": 'Bearer ' + login.test_login_user()}
  File "/Users/mohdsalekhan/Documents/HQM_API/Main_Project_API/User/User_Login.py", line 53, in test_login_user
    assert False
AssertionError
2022-02-21 15:54:57,652 :ERROR : test_user_currentUser :
Traceback (most recent call last):
  File "/Users/mohdsalekhan/Documents/HQM_API/Main_Project_API/User/User_Login.py", line 22, in test_login_user
    header_dict = e1.getAPIData("Headers", "Header")
  File "/Users/mohdsalekhan/Documents/HQM_API/Main_Project_API/Data_Config/Excel.py", line 19, in getAPIData
    sheet = book.get_sheet_by_name(data_section)
  File "/Users/mohdsalekhan/Library/Python/3.9/lib/python/site-packages/openpyxl/compat/__init__.py", line 38, in new_func1
    return func1(*args, **kwargs)
  File "/Users/mohdsalekhan/Library/Python/3.9/lib/python/site-packages/openpyxl/workbook/workbook.py", line 262, in get_sheet_by_name
    return self[name]
  File "/Users/mohdsalekhan/Library/Python/3.9/lib/python/site-packages/openpyxl/workbook/workbook.py", line 288, in __getitem__
    raise KeyError("Worksheet {0} does not exist.".format(key))
KeyError: 'Worksheet Headers does not exist.'

During handling of the above exception, another exception occurred:

Traceback (most recent call last):
  File "/Users/mohdsalekhan/Documents/HQM_API/Main_Project_API/User/User_CurrentUser.py", line 29, in test_user_currentUser
    "Authorization": 'Bearer ' + login.test_login_user()}
  File "/Users/mohdsalekhan/Documents/HQM_API/Main_Project_API/User/User_Login.py", line 53, in test_login_user
    assert False
AssertionError
2022-02-21 15:55:09,668 :INFO : test_user_currentUser :URL is provided
2022-02-21 15:55:09,683 :INFO : test_login_user :URL is provided
2022-02-21 15:55:09,698 :INFO : test_login_user :Exception occurred please find details below
2022-02-21 15:55:09,698 :INFO : test_login_user :Exception occurred please find details below
2022-02-21 15:55:09,698 :ERROR : test_login_user :'Worksheet Headers does not exist.'
Traceback (most recent call last):
  File "/Users/mohdsalekhan/Documents/HQM_API/Main_Project_API/User/User_Login.py", line 22, in test_login_user
    header_dict = e1.getAPIData("Headers", "Header")
  File "/Users/mohdsalekhan/Documents/HQM_API/Main_Project_API/Data_Config/Excel.py", line 19, in getAPIData
    sheet = book.get_sheet_by_name(data_section)
  File "/Users/mohdsalekhan/Library/Python/3.9/lib/python/site-packages/openpyxl/compat/__init__.py", line 38, in new_func1
    return func1(*args, **kwargs)
  File "/Users/mohdsalekhan/Library/Python/3.9/lib/python/site-packages/openpyxl/workbook/workbook.py", line 262, in get_sheet_by_name
    return self[name]
  File "/Users/mohdsalekhan/Library/Python/3.9/lib/python/site-packages/openpyxl/workbook/workbook.py", line 288, in __getitem__
    raise KeyError("Worksheet {0} does not exist.".format(key))
KeyError: 'Worksheet Headers does not exist.'
2022-02-21 15:55:09,698 :ERROR : test_login_user :'Worksheet Headers does not exist.'
Traceback (most recent call last):
  File "/Users/mohdsalekhan/Documents/HQM_API/Main_Project_API/User/User_Login.py", line 22, in test_login_user
    header_dict = e1.getAPIData("Headers", "Header")
  File "/Users/mohdsalekhan/Documents/HQM_API/Main_Project_API/Data_Config/Excel.py", line 19, in getAPIData
    sheet = book.get_sheet_by_name(data_section)
  File "/Users/mohdsalekhan/Library/Python/3.9/lib/python/site-packages/openpyxl/compat/__init__.py", line 38, in new_func1
    return func1(*args, **kwargs)
  File "/Users/mohdsalekhan/Library/Python/3.9/lib/python/site-packages/openpyxl/workbook/workbook.py", line 262, in get_sheet_by_name
    return self[name]
  File "/Users/mohdsalekhan/Library/Python/3.9/lib/python/site-packages/openpyxl/workbook/workbook.py", line 288, in __getitem__
    raise KeyError("Worksheet {0} does not exist.".format(key))
KeyError: 'Worksheet Headers does not exist.'
2022-02-21 15:55:09,700 :INFO : test_user_currentUser :Exception occurred please find details below
2022-02-21 15:55:09,700 :INFO : test_user_currentUser :Exception occurred please find details below
2022-02-21 15:55:09,700 :ERROR : test_user_currentUser :
Traceback (most recent call last):
  File "/Users/mohdsalekhan/Documents/HQM_API/Main_Project_API/User/User_Login.py", line 22, in test_login_user
    header_dict = e1.getAPIData("Headers", "Header")
  File "/Users/mohdsalekhan/Documents/HQM_API/Main_Project_API/Data_Config/Excel.py", line 19, in getAPIData
    sheet = book.get_sheet_by_name(data_section)
  File "/Users/mohdsalekhan/Library/Python/3.9/lib/python/site-packages/openpyxl/compat/__init__.py", line 38, in new_func1
    return func1(*args, **kwargs)
  File "/Users/mohdsalekhan/Library/Python/3.9/lib/python/site-packages/openpyxl/workbook/workbook.py", line 262, in get_sheet_by_name
    return self[name]
  File "/Users/mohdsalekhan/Library/Python/3.9/lib/python/site-packages/openpyxl/workbook/workbook.py", line 288, in __getitem__
    raise KeyError("Worksheet {0} does not exist.".format(key))
KeyError: 'Worksheet Headers does not exist.'

During handling of the above exception, another exception occurred:

Traceback (most recent call last):
  File "/Users/mohdsalekhan/Documents/HQM_API/Main_Project_API/User/User_CurrentUser.py", line 29, in test_user_currentUser
    "Authorization": 'Bearer ' + login.test_login_user()}
  File "/Users/mohdsalekhan/Documents/HQM_API/Main_Project_API/User/User_Login.py", line 53, in test_login_user
    assert False
AssertionError
2022-02-21 15:55:09,700 :ERROR : test_user_currentUser :
Traceback (most recent call last):
  File "/Users/mohdsalekhan/Documents/HQM_API/Main_Project_API/User/User_Login.py", line 22, in test_login_user
    header_dict = e1.getAPIData("Headers", "Header")
  File "/Users/mohdsalekhan/Documents/HQM_API/Main_Project_API/Data_Config/Excel.py", line 19, in getAPIData
    sheet = book.get_sheet_by_name(data_section)
  File "/Users/mohdsalekhan/Library/Python/3.9/lib/python/site-packages/openpyxl/compat/__init__.py", line 38, in new_func1
    return func1(*args, **kwargs)
  File "/Users/mohdsalekhan/Library/Python/3.9/lib/python/site-packages/openpyxl/workbook/workbook.py", line 262, in get_sheet_by_name
    return self[name]
  File "/Users/mohdsalekhan/Library/Python/3.9/lib/python/site-packages/openpyxl/workbook/workbook.py", line 288, in __getitem__
    raise KeyError("Worksheet {0} does not exist.".format(key))
KeyError: 'Worksheet Headers does not exist.'

During handling of the above exception, another exception occurred:

Traceback (most recent call last):
  File "/Users/mohdsalekhan/Documents/HQM_API/Main_Project_API/User/User_CurrentUser.py", line 29, in test_user_currentUser
    "Authorization": 'Bearer ' + login.test_login_user()}
  File "/Users/mohdsalekhan/Documents/HQM_API/Main_Project_API/User/User_Login.py", line 53, in test_login_user
    assert False
AssertionError
2022-02-21 15:56:40,564 :INFO : test_get_user_by_user_ID :URL is provided
2022-02-21 15:56:40,564 :INFO : test_get_user_by_user_ID :https://hqm-gateway-urtjok3rza-wl.a.run.app/user/login/userId/5
2022-02-21 15:56:40,580 :INFO : test_login_user :URL is provided
2022-02-21 15:56:40,597 :INFO : test_login_user :Exception occurred please find details below
2022-02-21 15:56:40,597 :INFO : test_login_user :Exception occurred please find details below
2022-02-21 15:56:40,598 :ERROR : test_login_user :'Worksheet Headers does not exist.'
Traceback (most recent call last):
  File "/Users/mohdsalekhan/Documents/HQM_API/Main_Project_API/User/User_Login.py", line 22, in test_login_user
    header_dict = e1.getAPIData("Headers", "Header")
  File "/Users/mohdsalekhan/Documents/HQM_API/Main_Project_API/Data_Config/Excel.py", line 19, in getAPIData
    sheet = book.get_sheet_by_name(data_section)
  File "/Users/mohdsalekhan/Library/Python/3.9/lib/python/site-packages/openpyxl/compat/__init__.py", line 38, in new_func1
    return func1(*args, **kwargs)
  File "/Users/mohdsalekhan/Library/Python/3.9/lib/python/site-packages/openpyxl/workbook/workbook.py", line 262, in get_sheet_by_name
    return self[name]
  File "/Users/mohdsalekhan/Library/Python/3.9/lib/python/site-packages/openpyxl/workbook/workbook.py", line 288, in __getitem__
    raise KeyError("Worksheet {0} does not exist.".format(key))
KeyError: 'Worksheet Headers does not exist.'
2022-02-21 15:56:40,598 :ERROR : test_login_user :'Worksheet Headers does not exist.'
Traceback (most recent call last):
  File "/Users/mohdsalekhan/Documents/HQM_API/Main_Project_API/User/User_Login.py", line 22, in test_login_user
    header_dict = e1.getAPIData("Headers", "Header")
  File "/Users/mohdsalekhan/Documents/HQM_API/Main_Project_API/Data_Config/Excel.py", line 19, in getAPIData
    sheet = book.get_sheet_by_name(data_section)
  File "/Users/mohdsalekhan/Library/Python/3.9/lib/python/site-packages/openpyxl/compat/__init__.py", line 38, in new_func1
    return func1(*args, **kwargs)
  File "/Users/mohdsalekhan/Library/Python/3.9/lib/python/site-packages/openpyxl/workbook/workbook.py", line 262, in get_sheet_by_name
    return self[name]
  File "/Users/mohdsalekhan/Library/Python/3.9/lib/python/site-packages/openpyxl/workbook/workbook.py", line 288, in __getitem__
    raise KeyError("Worksheet {0} does not exist.".format(key))
KeyError: 'Worksheet Headers does not exist.'
2022-02-21 15:56:40,600 :INFO : test_get_user_by_user_ID :Exception occurred please find details below
2022-02-21 15:56:40,600 :INFO : test_get_user_by_user_ID :Exception occurred please find details below
2022-02-21 15:56:40,601 :ERROR : test_get_user_by_user_ID :
Traceback (most recent call last):
  File "/Users/mohdsalekhan/Documents/HQM_API/Main_Project_API/User/User_Login.py", line 22, in test_login_user
    header_dict = e1.getAPIData("Headers", "Header")
  File "/Users/mohdsalekhan/Documents/HQM_API/Main_Project_API/Data_Config/Excel.py", line 19, in getAPIData
    sheet = book.get_sheet_by_name(data_section)
  File "/Users/mohdsalekhan/Library/Python/3.9/lib/python/site-packages/openpyxl/compat/__init__.py", line 38, in new_func1
    return func1(*args, **kwargs)
  File "/Users/mohdsalekhan/Library/Python/3.9/lib/python/site-packages/openpyxl/workbook/workbook.py", line 262, in get_sheet_by_name
    return self[name]
  File "/Users/mohdsalekhan/Library/Python/3.9/lib/python/site-packages/openpyxl/workbook/workbook.py", line 288, in __getitem__
    raise KeyError("Worksheet {0} does not exist.".format(key))
KeyError: 'Worksheet Headers does not exist.'

During handling of the above exception, another exception occurred:

Traceback (most recent call last):
  File "/Users/mohdsalekhan/Documents/HQM_API/Main_Project_API/User/User_GetUserByUserID.py", line 24, in test_get_user_by_user_ID
    "Authorization": 'Bearer '+login.test_login_user()}
  File "/Users/mohdsalekhan/Documents/HQM_API/Main_Project_API/User/User_Login.py", line 53, in test_login_user
    assert False
AssertionError
2022-02-21 15:56:40,601 :ERROR : test_get_user_by_user_ID :
Traceback (most recent call last):
  File "/Users/mohdsalekhan/Documents/HQM_API/Main_Project_API/User/User_Login.py", line 22, in test_login_user
    header_dict = e1.getAPIData("Headers", "Header")
  File "/Users/mohdsalekhan/Documents/HQM_API/Main_Project_API/Data_Config/Excel.py", line 19, in getAPIData
    sheet = book.get_sheet_by_name(data_section)
  File "/Users/mohdsalekhan/Library/Python/3.9/lib/python/site-packages/openpyxl/compat/__init__.py", line 38, in new_func1
    return func1(*args, **kwargs)
  File "/Users/mohdsalekhan/Library/Python/3.9/lib/python/site-packages/openpyxl/workbook/workbook.py", line 262, in get_sheet_by_name
    return self[name]
  File "/Users/mohdsalekhan/Library/Python/3.9/lib/python/site-packages/openpyxl/workbook/workbook.py", line 288, in __getitem__
    raise KeyError("Worksheet {0} does not exist.".format(key))
KeyError: 'Worksheet Headers does not exist.'

During handling of the above exception, another exception occurred:

Traceback (most recent call last):
  File "/Users/mohdsalekhan/Documents/HQM_API/Main_Project_API/User/User_GetUserByUserID.py", line 24, in test_get_user_by_user_ID
    "Authorization": 'Bearer '+login.test_login_user()}
  File "/Users/mohdsalekhan/Documents/HQM_API/Main_Project_API/User/User_Login.py", line 53, in test_login_user
    assert False
AssertionError
2022-02-21 16:02:23,317 :INFO : test_get_user_by_user_ID :URL is provided
2022-02-21 16:02:23,318 :INFO : test_get_user_by_user_ID :https://hqm-gateway-urtjok3rza-wl.a.run.app/user/login/userId/5
2022-02-21 16:02:23,318 :INFO : test_get_user_by_user_ID :https://hqm-gateway-urtjok3rza-wl.a.run.app/
2022-02-21 16:02:23,336 :INFO : test_login_user :URL is provided
2022-02-21 16:02:23,354 :INFO : test_login_user :Exception occurred please find details below
2022-02-21 16:02:23,354 :INFO : test_login_user :Exception occurred please find details below
2022-02-21 16:02:23,354 :ERROR : test_login_user :'Worksheet Headers does not exist.'
Traceback (most recent call last):
  File "/Users/mohdsalekhan/Documents/HQM_API/Main_Project_API/User/User_Login.py", line 22, in test_login_user
    header_dict = e1.getAPIData("Headers", "Header")
  File "/Users/mohdsalekhan/Documents/HQM_API/Main_Project_API/Data_Config/Excel.py", line 19, in getAPIData
    sheet = book.get_sheet_by_name(data_section)
  File "/Users/mohdsalekhan/Library/Python/3.9/lib/python/site-packages/openpyxl/compat/__init__.py", line 38, in new_func1
    return func1(*args, **kwargs)
  File "/Users/mohdsalekhan/Library/Python/3.9/lib/python/site-packages/openpyxl/workbook/workbook.py", line 262, in get_sheet_by_name
    return self[name]
  File "/Users/mohdsalekhan/Library/Python/3.9/lib/python/site-packages/openpyxl/workbook/workbook.py", line 288, in __getitem__
    raise KeyError("Worksheet {0} does not exist.".format(key))
KeyError: 'Worksheet Headers does not exist.'
2022-02-21 16:02:23,354 :ERROR : test_login_user :'Worksheet Headers does not exist.'
Traceback (most recent call last):
  File "/Users/mohdsalekhan/Documents/HQM_API/Main_Project_API/User/User_Login.py", line 22, in test_login_user
    header_dict = e1.getAPIData("Headers", "Header")
  File "/Users/mohdsalekhan/Documents/HQM_API/Main_Project_API/Data_Config/Excel.py", line 19, in getAPIData
    sheet = book.get_sheet_by_name(data_section)
  File "/Users/mohdsalekhan/Library/Python/3.9/lib/python/site-packages/openpyxl/compat/__init__.py", line 38, in new_func1
    return func1(*args, **kwargs)
  File "/Users/mohdsalekhan/Library/Python/3.9/lib/python/site-packages/openpyxl/workbook/workbook.py", line 262, in get_sheet_by_name
    return self[name]
  File "/Users/mohdsalekhan/Library/Python/3.9/lib/python/site-packages/openpyxl/workbook/workbook.py", line 288, in __getitem__
    raise KeyError("Worksheet {0} does not exist.".format(key))
KeyError: 'Worksheet Headers does not exist.'
2022-02-21 16:02:23,360 :INFO : test_get_user_by_user_ID :Exception occurred please find details below
2022-02-21 16:02:23,360 :INFO : test_get_user_by_user_ID :Exception occurred please find details below
2022-02-21 16:02:23,360 :ERROR : test_get_user_by_user_ID :
Traceback (most recent call last):
  File "/Users/mohdsalekhan/Documents/HQM_API/Main_Project_API/User/User_Login.py", line 22, in test_login_user
    header_dict = e1.getAPIData("Headers", "Header")
  File "/Users/mohdsalekhan/Documents/HQM_API/Main_Project_API/Data_Config/Excel.py", line 19, in getAPIData
    sheet = book.get_sheet_by_name(data_section)
  File "/Users/mohdsalekhan/Library/Python/3.9/lib/python/site-packages/openpyxl/compat/__init__.py", line 38, in new_func1
    return func1(*args, **kwargs)
  File "/Users/mohdsalekhan/Library/Python/3.9/lib/python/site-packages/openpyxl/workbook/workbook.py", line 262, in get_sheet_by_name
    return self[name]
  File "/Users/mohdsalekhan/Library/Python/3.9/lib/python/site-packages/openpyxl/workbook/workbook.py", line 288, in __getitem__
    raise KeyError("Worksheet {0} does not exist.".format(key))
KeyError: 'Worksheet Headers does not exist.'

During handling of the above exception, another exception occurred:

Traceback (most recent call last):
  File "/Users/mohdsalekhan/Documents/HQM_API/Main_Project_API/User/User_GetUserByUserID.py", line 25, in test_get_user_by_user_ID
    "Authorization": 'Bearer '+login.test_login_user()}
  File "/Users/mohdsalekhan/Documents/HQM_API/Main_Project_API/User/User_Login.py", line 53, in test_login_user
    assert False
AssertionError
2022-02-21 16:02:23,360 :ERROR : test_get_user_by_user_ID :
Traceback (most recent call last):
  File "/Users/mohdsalekhan/Documents/HQM_API/Main_Project_API/User/User_Login.py", line 22, in test_login_user
    header_dict = e1.getAPIData("Headers", "Header")
  File "/Users/mohdsalekhan/Documents/HQM_API/Main_Project_API/Data_Config/Excel.py", line 19, in getAPIData
    sheet = book.get_sheet_by_name(data_section)
  File "/Users/mohdsalekhan/Library/Python/3.9/lib/python/site-packages/openpyxl/compat/__init__.py", line 38, in new_func1
    return func1(*args, **kwargs)
  File "/Users/mohdsalekhan/Library/Python/3.9/lib/python/site-packages/openpyxl/workbook/workbook.py", line 262, in get_sheet_by_name
    return self[name]
  File "/Users/mohdsalekhan/Library/Python/3.9/lib/python/site-packages/openpyxl/workbook/workbook.py", line 288, in __getitem__
    raise KeyError("Worksheet {0} does not exist.".format(key))
KeyError: 'Worksheet Headers does not exist.'

During handling of the above exception, another exception occurred:

Traceback (most recent call last):
  File "/Users/mohdsalekhan/Documents/HQM_API/Main_Project_API/User/User_GetUserByUserID.py", line 25, in test_get_user_by_user_ID
    "Authorization": 'Bearer '+login.test_login_user()}
  File "/Users/mohdsalekhan/Documents/HQM_API/Main_Project_API/User/User_Login.py", line 53, in test_login_user
    assert False
AssertionError
2022-02-21 16:10:12,337 :INFO : test_get_user_by_user_ID :URL is provided
2022-02-21 16:10:12,338 :INFO : test_get_user_by_user_ID :https://hqm-gateway-urtjok3rza-wl.a.run.app/user/login/userId/5
2022-02-21 16:10:12,338 :INFO : test_get_user_by_user_ID :https://hqm-gateway-urtjok3rza-wl.a.run.app/
2022-02-21 16:10:12,356 :INFO : test_login_user :URL is provided
2022-02-21 16:10:12,356 :INFO : test_login_user :Header is provided
2022-02-21 16:10:12,371 :INFO : test_login_user :Payload is provided and as below:
2022-02-21 16:10:12,371 :INFO : test_login_user :{'userName': 'madara', 'password': '987654321'}
2022-02-21 16:10:13,240 :INFO : test_login_user :Response is as below:
2022-02-21 16:10:13,241 :INFO : test_login_user :{"timestamp":"2022-02-21T10:40:13.321+00:00","status":415,"error":"Unsupported Media Type","path":"/user/login/generate-token"}
2022-02-21 16:10:13,245 :INFO : test_login_user :Exception occurred please find details below
2022-02-21 16:10:13,245 :INFO : test_login_user :Exception occurred please find details below
2022-02-21 16:10:13,245 :ERROR : test_login_user :Invalid status code
Traceback (most recent call last):
  File "/Users/mohdsalekhan/Documents/HQM_API/Main_Project_API/User/User_Login.py", line 41, in test_login_user
    assert resp.status_code == 200, 'Invalid status code'
AssertionError: Invalid status code
2022-02-21 16:10:13,245 :ERROR : test_login_user :Invalid status code
Traceback (most recent call last):
  File "/Users/mohdsalekhan/Documents/HQM_API/Main_Project_API/User/User_Login.py", line 41, in test_login_user
    assert resp.status_code == 200, 'Invalid status code'
AssertionError: Invalid status code
2022-02-21 16:10:13,249 :INFO : test_get_user_by_user_ID :Exception occurred please find details below
2022-02-21 16:10:13,249 :INFO : test_get_user_by_user_ID :Exception occurred please find details below
2022-02-21 16:10:13,250 :ERROR : test_get_user_by_user_ID :
Traceback (most recent call last):
  File "/Users/mohdsalekhan/Documents/HQM_API/Main_Project_API/User/User_Login.py", line 41, in test_login_user
    assert resp.status_code == 200, 'Invalid status code'
AssertionError: Invalid status code

During handling of the above exception, another exception occurred:

Traceback (most recent call last):
  File "/Users/mohdsalekhan/Documents/HQM_API/Main_Project_API/User/User_GetUserByUserID.py", line 27, in test_get_user_by_user_ID
    "Authorization": 'Bearer '+login.test_login_user()}
  File "/Users/mohdsalekhan/Documents/HQM_API/Main_Project_API/User/User_Login.py", line 54, in test_login_user
    assert False
AssertionError
2022-02-21 16:10:13,250 :ERROR : test_get_user_by_user_ID :
Traceback (most recent call last):
  File "/Users/mohdsalekhan/Documents/HQM_API/Main_Project_API/User/User_Login.py", line 41, in test_login_user
    assert resp.status_code == 200, 'Invalid status code'
AssertionError: Invalid status code

During handling of the above exception, another exception occurred:

Traceback (most recent call last):
  File "/Users/mohdsalekhan/Documents/HQM_API/Main_Project_API/User/User_GetUserByUserID.py", line 27, in test_get_user_by_user_ID
    "Authorization": 'Bearer '+login.test_login_user()}
  File "/Users/mohdsalekhan/Documents/HQM_API/Main_Project_API/User/User_Login.py", line 54, in test_login_user
    assert False
AssertionError
2022-02-21 16:16:21,141 :INFO : test_get_user_by_user_ID :URL is provided
2022-02-21 16:16:21,145 :INFO : test_login_user :Logging in as admin
2022-02-21 16:16:21,161 :INFO : test_login_user :Fetching payload data for admin
2022-02-21 16:16:21,887 :INFO : test_login_user :Bearer token is 
2022-02-21 16:16:21,887 :INFO : test_login_user :eyJhbGciOiJIUzI1NiJ9.eyJzdWIiOiJtYWRhcmEiLCJleHAiOjE2NDU1MTIzODEsImlhdCI6MTY0NTQ0MDM4MX0.AjhK6pyrpoeP590Mxi6ETbq6katVAYeWCKr3qfllLRw
2022-02-21 16:16:21,887 :INFO : test_login_user :200
2022-02-21 16:16:21,887 :INFO : test_login_user :Successfully Logged in
2022-02-21 16:16:21,888 :INFO : test_get_user_by_user_ID :Header is provided
2022-02-21 16:16:22,413 :INFO : test_get_user_by_user_ID :Response is sent
2022-02-21 16:16:22,413 :INFO : test_get_user_by_user_ID :The fetched user details is as below:
2022-02-21 16:16:22,413 :INFO : test_get_user_by_user_ID :{"userId":5,"userName":"tuntun_pandit","firstName":"Tuntun ","lastName":"Kumar","email":"karan_kk@yahoo.com","phone":"6283340052","hubatch":{"huBatchId":2,"huBatchTitle":"12.2","startDate":"2022-01-03","endDate":"2022-02-07"},"userRole":"NORMAL"}
2022-02-21 16:16:22,413 :INFO : test_get_user_by_user_ID :Status code is validated
2022-02-21 16:18:44,820 :INFO : test_user_currentUser :URL is provided
2022-02-21 16:18:44,824 :INFO : test_login_user :Logging in as admin
2022-02-21 16:18:44,840 :INFO : test_login_user :Fetching payload data for admin
2022-02-21 16:18:46,624 :INFO : test_login_user :Bearer token is 
2022-02-21 16:18:46,624 :INFO : test_login_user :eyJhbGciOiJIUzI1NiJ9.eyJzdWIiOiJtYWRhcmEiLCJleHAiOjE2NDU1MTI1MjYsImlhdCI6MTY0NTQ0MDUyNn0.Ig4seDo_u1cGYy8KRUWMj9dqED8Xaz0-f-uMD1u_mI0
2022-02-21 16:18:46,624 :INFO : test_login_user :200
2022-02-21 16:18:46,625 :INFO : test_login_user :Successfully Logged in
2022-02-21 16:18:46,625 :INFO : test_user_currentUser :Header is provided
2022-02-21 16:18:47,141 :INFO : test_user_currentUser :Response is as below:
2022-02-21 16:18:47,142 :INFO : test_user_currentUser :{"userId":76,"userName":"madara","firstName":"madara","lastName":"Uchihaaa","email":"madara@gmail.com","phone":"987652321","hubatch":{"huBatchId":3,"huBatchTitle":"12.9","startDate":null,"endDate":null},"userRole":"NORMAL"}
2022-02-21 16:18:47,142 :INFO : test_user_currentUser :Status code validated
>>>>>>> e2e38304767dce09a8d4e85ce77f80fd016bd0ae
